<?xml version="1.0" encoding="utf-8"?>
<!-- This URDF was automatically created by SolidWorks to URDF Exporter! Originally created by Stephen Brawner (brawner@gmail.com) 
     Commit Version: 1.5.1-0-g916b5db  Build Version: 1.5.7152.31018
     For more information, please see http://wiki.ros.org/sw_urdf_exporter -->
<robot
  name="pegasus_mini">
  <link
    name="base_link">
    <inertial>
      <origin
        xyz="0.00365853589713711 0.000380388416027 0.038426540116575"
        rpy="0 0 0" />
      <mass
        value="3.43703942926342" />
      <inertia
        ixx="0.0385534517594733"
        ixy="-2.58460031727792E-06"
        ixz="-0.000978593513309931"
        iyy="0.0579937355300671"
        iyz="-2.33622278232532E-06"
        izz="0.0836747902119563" />
    </inertial>
    <visual>
      <origin
        xyz="0 0 0"
        rpy="0 0 0" />
      <geometry>
        <mesh
          filename="package://pegasus_base/meshes/base_link.STL" />
      </geometry>
      <material
        name="">
        <color
          rgba="0.792156862745098 0.819607843137255 0.933333333333333 1" />
      </material>
    </visual>
    <collision>
      <origin
        xyz="0 0 0"
        rpy="0 0 0" />
      <geometry>
        <mesh
          filename="package://pegasus_base/meshes/base_link.STL" />
      </geometry>
    </collision>
  </link>
  <link
    name="leftwheel_link">
    <inertial>
      <origin
        xyz="3.88578058618805E-16 -2.77555756156289E-17 -0.0150000000000029"
        rpy="0 0 0" />
      <mass
        value="0.232013920708616" />
      <inertia
        ixx="0.000277320036972709"
        ixy="2.88764468097228E-33"
        ixz="-6.09677500703944E-18"
        iyy="0.000277320036972709"
        iyz="-1.2180919950052E-19"
        izz="0.000538249657591166" />
    </inertial>
    <visual>
      <origin
        xyz="0 0 0"
        rpy="0 0 0" />
      <geometry>
        <mesh
          filename="package://pegasus_base/meshes/leftwheel_link.STL" />
      </geometry>
      <material
        name="">
        <color
          rgba="0.298039215686275 0.298039215686275 0.298039215686275 1" />
      </material>
    </visual>
    <collision>
      <origin
        xyz="0 0 0"
        rpy="0 0 0" />
      <geometry>
        <mesh
          filename="package://pegasus_base/meshes/leftwheel_link.STL" />
      </geometry>
    </collision>
  </link>
  <joint
    name="leftwheel_joint "
    type="continuous">
    <origin
      xyz="0 0.097 0"
      rpy="1.5708 0 0" />
    <parent
      link="base_link" />
    <child
      link="leftwheel_link" />
    <axis
      xyz="0 0 1" />
  </joint>
  <link
    name="rightwheel_link">
    <inertial>
      <origin
        xyz="0 0 -0.015000000000003"
        rpy="0 0 0" />
      <mass
        value="0.232013920708616" />
      <inertia
        ixx="0.000277320036972709"
        ixy="-4.2351647362715E-22"
        ixz="1.31491838759612E-20"
        iyy="0.000277320036972708"
        iyz="1.47374866999901E-19"
        izz="0.000538249657591165" />
    </inertial>
    <visual>
      <origin
        xyz="0 0 0"
        rpy="0 0 0" />
      <geometry>
        <mesh
          filename="package://pegasus_base/meshes/rightwheel_link.STL" />
      </geometry>
      <material
        name="">
        <color
          rgba="0.298039215686275 0.298039215686275 0.298039215686275 1" />
      </material>
    </visual>
    <collision>
      <origin
        xyz="0 0 0"
        rpy="0 0 0" />
      <geometry>
        <mesh
          filename="package://pegasus_base/meshes/rightwheel_link.STL" />
      </geometry>
    </collision>
  </link>
  <joint
    name="rightwheel_joint"
    type="continuous">
    <origin
      xyz="0 -0.097 0"
      rpy="1.5708 0.020691 3.1416" />
    <parent
      link="base_link" />
    <child
      link="rightwheel_link" />
    <axis
      xyz="0 0 1" />
  </joint>
  <link
    name="laser">
    <inertial>
      <origin
        xyz="-0.000130075896247028 -0.0143069860138316 0.000607372907348469"
        rpy="0 0 0" />
      <mass
        value="0.00676513423885409" />
      <inertia
        ixx="3.1177993907721E-06"
        ixy="3.88370771935945E-09"
        ixz="-2.61140984837153E-08"
        iyy="5.59776117110549E-06"
        iyz="-2.52899772792506E-08"
        izz="3.01419160932951E-06" />
    </inertial>
    <visual>
      <origin
        xyz="0 0 0"
        rpy="0 0 0" />
      <geometry>
        <mesh
          filename="package://pegasus_base/meshes/lidar_link.STL" />
      </geometry>
      <material
        name="">
        <color
          rgba="0.43921568627451 0.43921568627451 0.43921568627451 1" />
      </material>
    </visual>
    <collision>
      <origin
        xyz="0 0 0"
        rpy="0 0 0" />
      <geometry>
        <mesh
          filename="package://pegasus_base/meshes/lidar_link.STL" />
      </geometry>
    </collision>
  </link>
  <joint
    name="laser_joint"
    type="fixed">
    <origin rpy="0 0 3.1415926" xyz="0 0 0.05" />    
    <parent
      link="base_link" />
    <child
      link="laser" />
  </joint>

    <gazebo>
    <plugin filename="libgazebo_ros_diff_drive.so" name="differential_drive_controller_front">
      <rosDebugLevel>Debug</rosDebugLevel>
      <publishWheelTF>True</publishWheelTF>
      <publishTf>1</publishTf>
      <publishWheelJointState>true</publishWheelJointState>
      <alwaysOn>true</alwaysOn>
      <updateRate>100.0</updateRate>
      <leftJoint>leftwheel_joint</leftJoint>
      <rightJoint>rightwheel_joint</rightJoint>
      <wheelSeparation>0.390</wheelSeparation>
      <wheelDiameter>0.14393</wheelDiameter>
      <broadcastTF>1</broadcastTF>
      <wheelTorque>30</wheelTorque>
      <wheelAcceleration>1.8</wheelAcceleration>
      <commandTopic>cmd_vel</commandTopic>
      <odometryFrame>odom</odometryFrame>
      <odometryTopic>odom</odometryTopic>
      <robotBaseFrame>base_link</robotBaseFrame>
    </plugin>
  </gazebo>

</robot>



